<style>
.highlight {color:red}
.elegant {color:blue}
</style>

# 08.例外處理

![](https://hackmd.io/_uploads/ByEfAg__h.jpg)

在 Python 中，我們使用【例外處理】(exception handling) 這個詞，而不是【錯誤處理】(error handling)，這是因為在 Python 中，例外不一定都是錯誤。

例外是在執行程式時發生的特殊事件或情況，可能是錯誤，如 TypeError 或ZeroDivisionError，也可能是正常情況下的事件，例如迭代過程中到達了迭代器的結尾。當這些特殊情況發生時，Python 將會關閉正常的程式流程，並引發一個例外，讓我們能夠適當地處理例外情況，常見的例外類別有：

- Exception：所有例外類別的基類。
- KeyError：當使用字典中不存在的鍵時引發。
- TypeError：當操作或函式應用於不適當的類型時引發。
- ValueError：當內建操作或函式應用於具有適當類型但無效內容的對象時引發。
- IndexError：當嘗試訪問無效索引的序列（例如list、tuple或字串）時引發。
- ZeroDivisionError：當除數為零時引發。

![image.png](https://hackmd.io/_uploads/HyvwfT_7a.png)

Python 中的例外類別有一個繼承層次(hierarchy)，所有的例外類別都是由 BaseException 類別繼承而來的。

## 例外基本用法

Python 可利用 try-except 陳述 (try-except statement) 讓程式設計師自行處理例外，而不會拋出預設的錯誤訊息，讓使用者錯愕。

```python=
try:
    # 執行可能引發異常的程式區塊
    num = int(input('輸入整數：'))
except Exception as e:
    # 處理相應例外的程式碼
    print('請輸入阿拉伯數字')
    print(f'錯誤訊息為{e}')
else:
    # 當try程式區塊成功執行時，會執行此區塊的程式碼(可省略)
    print(f"{num} 為 {'奇數' if num% 2 else '偶數'}")
finally:
    # 無論try程式區塊是否發生異常，都執行finally程式碼區塊的程式碼(可省略)
    print('再見')
```
![](https://hackmd.io/_uploads/HkMZTlOd3.png)

可能會產生例外的程式碼放在 try 的區塊中，例外後的處置則放在 except 區塊中，else 區塊通常是放沒有發生例外時的程式碼(可省略)，無論有無例外一定會執行的程式放在 finally 區塊(可省略)。

發生例外有非常多種原因，若想針對原因進行不同的處理，可參考下列範例：

```python=
try:
    num= int(input('輸入整數：'))
except ValueError as err1:
    print(f'請輸入阿拉伯數字 ({err1})')
except TypeError as err2:
    print(f'請輸入整數 ({err2})')
except KeyboardInterrupt:
    print('使用者中斷程式')
except Exception as e:
   print(f'錯誤訊息：{e}')
else:
    print(f"{num} 為 {'奇數' if num% 2 else '偶數'}")
finally:
    print('再見')
```
> 建議在處理例外的最後加上 except Exception as e: 除了可以捕捉所有的例外之外，還可以取得例外物件的相關資訊，例如例外類別、例外訊息等等。

Exception 是 Python 的一個基礎的例外類別 (class)。而 e 是一個變數，用於存儲發生的例外物件 (Exception object)，可以通過這個物件來獲取例外相關的屬性和方法。

例外物件常用的屬性包括：
- args：返回一個包含例外相關信息的tuple
- errno：返回發生例外時的錯誤編號
- strerror：返回一個描述例外錯誤的字串
- filename：返回觸發例外的文件名

以下是例外物件屬性的處理範例
```python=
try:
  with open('member.txt', 'r', encoding='UTF-8') as f:
    print(f.read())
except Exception as e:
    print('開檔發生錯誤...')
    print(f'錯誤代碼為：{e.errno}')
    print(f'錯誤訊息為：{e.strerror}')
    print(f'錯誤檔案為：{e.filename}')
```

## 手動引發例外

在某些特定的時機，我們可以利用 raise 語句，根據自己的需求主動引發例外，以便更好的控制程序的執行流程，例如：

- 當我們需要將一個錯誤或例外向上傳遞時，可以使用 raise 語句將例外引發至呼叫程式，以便上層程式進行處理。
- 當條件不符合要求時，需要主動引發例外，並將例外與特定的例外類型關聯起來。例如，當我們在寫函數時，發現參數值不符合預期時，可以利用 raise ValueError 語句，主動引發一個 ValueError 例外
- 當我們需要在測試代碼時，手動引發一個例外，以便測試代碼的容錯性。

![image.png](https://hackmd.io/_uploads/SJ9q_aO7p.png)

### 1.將例外向上傳遞：
在這個例子中，如果 func1() 函數引發例外，則該例外會被傳遞到 func2() 函數中。在這裡，我們可以對例外進行處理，並使用 raise 語句將異常向上傳遞，以便更高層級的函數或主程式進行處理。
```python=
def func1():
    # ...
    raise Exception("在func1函數發生例外")

def func2():
    try:
        func1()
    except Exception as e:
        print(e)

```

### 2.主動引發一個例外：
在這個例子中，我們定義了一個 divide 函數，該函數將兩個數字作為參數並進行除法運算。如果除數 b 為零，則該函數會引發一個 ValueError 例外。
```python=
def divide(a, b):
    if b == 0:
        raise ValueError("不能除以0")
    return a / b
```

### 3.測試代碼容錯性：
在這個例子中，我們定義了一個 divide 函數，該函數將兩個數字作為參數並進行除法運算。如果除數 b 為零，則該函數會引發一個 ValueError 例外。

在這個例子中，該代碼中的斷言 assert 語句未通過，則該函數會主動引發一個 AssertionError 例外。
```python=
def test(lst):
    assert len(lst) == 4, "個數應為 4"

test( [1, 2, 3])
```
## 斷言 assert 的使用
assert 語句的使用時機通常是在開發階段進行代碼除錯，以及測試階段驗證程式的健壯性時之用。assert  斷言某個條件是否為真，並在條件不成立時引發 AssertionError 例外，其語法為 `assert <條件>, <錯誤訊息>`

![image.png](https://hackmd.io/_uploads/S1f6vpuX6.png)


使用範例：
```python=
def calculate_rectangle_area(length, width):
    assert isinstance(length, (int, float)), "長度必須是數值型別"
    assert isinstance(width, (int, float)), "寬度必須是數值型別"
    assert length > 0, "長度必須為正數"
    assert width > 0, "寬度必須為正數"    
    return length * width

print(calculate_rectangle_area(-1, 5))        # 引發 AssertionError: 長度必須為正數
print(calculate_rectangle_area(2, 'hello'))   # 引發 AssertionError: 寬度必須是數值型別
print(calculate_rectangle_area(3, 4))         # 返回 12
```